Workbook

Sheet Main
A1: Service Code | B1: SERV_PANEL_NAME | C1: S_DATE | D1: E_DATE | E1: Open/Closed | F1: Type | G1: ประเภทบริการ | H1: Agency Category | I1: Flow Type | J1: Barcode | K1: No. of fields | L1: คู่ค้า | M1: ค่าธรรมเนียม (Fee) | N1: AMOUNT MIN | O1: AMOUNT MAX | P1: PER DAY | Q1: ใบรับเงิน/ ใบกำกับภาษีอย่างย่อ | R1: ใบรับเงิน/ ใบกำกับภาษีเต็มรูป | S1: Tax Code | T1: ใบรับเงิน | U1: วันที่มีรายการล่าสุด | V1: STAT 2023 | W1: STAT 2023/m | X1: STAT 2023/Priority | Y1: STAT 2022 | Z1: STAT 2022/m | AA1: STAT 2022/Priority | AB1: STAT 2021 | AC1: STAT 2021/m | AD1: STAT 2021/Priority | AE1: STAT 2023-2021/Average | AF1: Priority/Sum | AG1: ใบขอใช้บริการ | AH1: ใบบันทึกรายการ | AI1: Comment
A2: 102 | B2: อิออน สินเชื่อ ยัวร์แคช OffLine | C2: 42186 | E2: Closed | F2: OFFLINE | G2: บริการรับชำระ | M2: 0 | N2: 0 | O2: 0 | P2: 100000 | T2: YES | U2: #N/A | V2: =VLOOKUP(A2,'2023 Stats'!$B$2:$D$192,3,FALSE) -> #N/A | W2: #N/A | Y2: #N/A | Z2: #N/A | AB2: #N/A | AE2: #N/A
A3: 103 | B3: จ่ายเงินบริการ KBANK2POST ของ ธ.กสิกรไทย | C3: 42186 | E3: Closed | F3: OFFLINE | G3: บริการรับชำระ | M3: 0 | N3: 0 | O3: 0 | P3: 100000 | T3: YES | U3: #N/A | V3: =VLOOKUP(A3,'2023 Stats'!$B$2:$D$192,3,FALSE) -> #N/A | W3: #N/A | Y3: #N/A | Z3: #N/A | AB3: #N/A | AE3: #N/A
A4: 104 | B4: รับเงินฝาก ธ.ไทยเครดิต (บาร์โค้ด) Offline | C4: 42186 | E4: Closed | F4: OFFLINE | G4: บริการรับชำระ | M4: 0 | N4: 0 | O4: 0 | P4: 100000 | T4: YES | U4: #N/A | V4: =VLOOKUP(A4,'2023 Stats'!$B$2:$D$192,3,FALSE) -> #N/A | W4: #N/A | Y4: #N/A | Z4: #N/A | AB4: #N/A | AE4: #N/A
A5: 1819 | B5: เงินฝากสมาชิกตราไปรษณียากร | C5: 42186 | E5: Open | F5: OFFLINE | G5: บริการรับชำระ | H5: Postal service | M5: 0 | N5: 1 | O5: 50000 | P5: 100000 | T5: YES | U5: 31/12/2023 | V5: =VLOOKUP(A5,'2023 Stats'!$B$2:$D$192,3,FALSE) -> 4383 | W5: 1096 | Y5: 4211 | Z5: 351 | AB5: #N/A | AE5: 723 | AH5: YES
A6: 10014 | B6: ส่งเงินเวสเทิร์นยูเนี่ยน/สอบถามค่าบริการ | C6: 42186 | E6: Open | F6: ONLINE | G6: บริการรับชำระ | I6: Western Union not to be done in Agency | L6: WU | M6: 0 | N6: 0 | O6: 0 | P6: 100000 | T6: YES | V6: =VLOOKUP(A6,'2023 Stats'!$B$2:$D$192,3,FALSE) -> #N/A | W6: #N/A | Y6: #N/A | Z6: #N/A | AB6: #N/A | AE6: #N/A
A7: 10015 | B7: จ่ายเงินเวสเทิร์นยูเนี่ยน | C7: 42186 | E7: Open | F7: ONLINE | G7: บริการรับชำระ | I7: Western Union not to be done in Agency | L7: WU | M7: 0 | N7: 0 | O7: 0 | P7: 100000 | T7: YES | V7: =VLOOKUP(A7,'2023 Stats'!$B$2:$D$192,3,FALSE) -> #N/A | W7: #N/A | Y7: #N/A | Z7: #N/A | AB7: #N/A | AE7: #N/A | AH7: YES
A8: 10016 | B8: ตรวจสอบสถานะจ่ายเงิน เวสเทิร์นยูเนี่ยน | C8: 42005 | E8: Open | F8: ONLINE | G8: บริการรับชำระ | I8: Western Union not to be done in Agency | L8: WU | M8: 0 | N8: 0 | O8: 0 | P8: 100000 | T8: YES | V8: =VLOOKUP(A8,'2023 Stats'!$B$2:$D$192,3,FALSE) -> #N/A | W8: #N/A | Y8: #N/A | Z8: #N/A | AB8: #N/A | AE8: #N/A | AI8: Inquiry
A9: 10017 | B9: สอบถามค่าบริการ | C9: 42005 | E9: Open | F9: ONLINE | G9: บริการรับชำระ | I9: Western Union not to be done in Agency | L9: WU | M9: 0 | N9: 0 | O9: 0 | P9: 100000 | T9: YES | V9: =VLOOKUP(A9,'2023 Stats'!$B$2:$D$192,3,FALSE) -> #N/A | W9: #N/A | Y9: #N/A | Z9: #N/A | AB9: #N/A | AE9: #N/A | AI9: Inquiry
A10: 10018 | B10: F2ZOOM | C10: 42005 | E10: Open | F10: ONLINE | G10: บริการรับชำระ | I10: Western Union not to be done in Agency | L10: WU | M10: 0 | N10: 0 | O10: 0 | P10: 100000 | T10: YES | V10: =VLOOKUP(A10,'2023 Stats'!$B$2:$D$192,3,FALSE) -> #N/A | W10: #N/A | Y10: #N/A | Z10: #N/A | AB10: #N/A | AE10: #N/A | AI10: Inquiry
A11: 10020 | B11: ลงทะเบียนกล่องดิจิตอล | C11: 42736 | E11: Closed | F11: OFFLINE | G11: บริการรับชำระ | M11: 0 | N11: 1 | O11: 0 | P11: 100000 | T11: YES | U11: #N/A | V11: =VLOOKUP(A11,'2023 Stats'!$B$2:$D$192,3,FALSE) -> #N/A | W11: #N/A | Y11: #N/A | Z11: #N/A | AB11: #N/A | AE11: #N/A | AI11: ปิดใช้บริการ
A12: 10021 | B12: ตรวจสอบลายมือชื่อผู้มีสิทธิ์สั่งจ่าย | C12: 42736 | E12: Closed | F12: OFFLINE/iFrame | G12: บริการรับชำระ | M12: 0 | N12: 1 | O12: 0 | P12: 100000 | T12: YES | U12: #N/A | V12: =VLOOKUP(A12,'2023 Stats'!$B$2:$D$192,3,FALSE) -> #N/A | W12: #N/A | Y12: #N/A | Z12: #N/A | AB12: #N/A | AE12: #N/A
A13: 10022 | B13: Drop-off | C13: 43344 | E13: Closed | F13: OFFLINE/iFrame | G13: บริการรับชำระ | H13: Postal service | M13: 0 | N13: 1 | O13: 0 | P13: 100000 | T13: YES | U13: #N/A | V13: =VLOOKUP(A13,'2023 Stats'!$B$2:$D$192,3,FALSE) -> #N/A | W13: #N/A | Y13: #N/A | Z13: #N/A | AB13: #N/A | AE13: #N/A | AI13: สอบถามเฉยๆ
A14: 10023 | B14: ตรวจสอบ Wallet@Post | C14: 43101 | E14: Open | F14: OFFLINE/iFrame | G14: บริการรับชำระ | H14: Check Wallet@post | M14: 0 | N14: 0 | O14: 0 | P14: 100000 | T14: YES | V14: =VLOOKUP(A14,'2023 Stats'!$B$2:$D$192,3,FALSE) -> #N/A | W14: #N/A | Y14: #N/A | Z14: #N/A | AB14: #N/A | AE14: #N/A | AI14: Inquiry
A15: 10025 | B15: ตรวจสอบรายชื่อบุคคลที่ห้ามทำธุรกรรม | C15: 43983 | E15: Closed | F15: OFFLINE/iFrame | G15: บริการรับชำระ | H15: Service payment | M15: 0 | N15: 0 | O15: 0 | P15: 100000 | T15: YES | U15: #N/A | V15: =VLOOKUP(A15,'2023 Stats'!$B$2:$D$192,3,FALSE) -> #N/A | W15: #N/A | Y15: #N/A | Z15: #N/A | AB15: #N/A | AE15: #N/A | AI15: สอบถามเฉยๆ
A16: 10050 | B16: Pay@WU Order Payment | C16: 43733 | E16: Open | F16: ONLINE | G16: บริการรับชำระ | I16: Not to be offered via Agency | L16: WU | M16: 0 | N16: 1 | O16: 50000 | P16: 100000 | T16: YES | U16: 31/12/2023 | V16: =VLOOKUP(A16,'2023 Stats'!$B$2:$D$192,3,FALSE) -> #N/A | W16: #N/A | Y16: 23 | Z16: 2 | AB16: #N/A | AE16: #N/A
A17: 10051 | B17: Pay@WU Order Refund | C17: 43733 | E17: Open | F17: ONLINE | G17: บริการรับชำระ | I17: Not to be offered via Agency | L17: WU | M17: 0 | N17: 1 | O17: 50000 | P17: 100000 | T17: YES | U17: 31/12/2023 | V17: =VLOOKUP(A17,'2023 Stats'!$B$2:$D$192,3,FALSE) -> #N/A | W17: #N/A | Y17: 23 | Z17: 2 | AB17: #N/A | AE17: #N/A | AH17: YES
A18: 20000 | B18: Fix Form Search | C18: 42186 | E18: Closed | F18: OFFLINE | G18: บริการรับชำระ | M18: 0 | N18: 0 | O18: 0 | P18: 100000 | T18: YES | U18: #N/A | V18: =VLOOKUP(A18,'2023 Stats'!$B$2:$D$192,3,FALSE) -> #N/A | W18: #N/A | Y18: #N/A | Z18: #N/A | AB18: #N/A | AE18: #N/A
A19: 30078 | B19: รับชำระค่าสินค้าเรียกเก็บเงินที่บ้าน - DPost | C19: 42182 | E19: Open | F19: ONLINE | G19: บริการรับชำระ | H19: Dpost payment | I19: Special Case | J19: No Barcode | K19: 10 | L19: บท. | M19: 0 | N19: 1 | O19: 50000 | P19: 100000 | T19: YES | U19: 31/12/2023 | V19: =VLOOKUP(A19,'2023 Stats'!$B$2:$D$192,3,FALSE) -> #N/A | W19: #N/A | X19: 1 | Y19: 22574347 | Z19: 1881196 | AA19: 1 | AB19: #N/A | AE19: #N/A | AF19: 1 | AH19: YES
A20: 30079 | B20: รับชำระค่าสินค้าเรียกเก็บเงินที่บ้าน (TND) | C20: 44227 | E20: Open | F20: ONLINE | G20: บริการรับชำระ | H20: Dpost payment | L20: บท. | M20: 0 | N20: 1 | O20: 50000 | P20: 100000 | T20: YES | U20: 31/12/2023 | V20: =VLOOKUP(A20,'2023 Stats'!$B$2:$D$192,3,FALSE) -> #N/A | W20: #N/A | Y20: #N/A | Z20: #N/A | AB20: #N/A | AE20: #N/A | AH20: YES
A21: 30156 | B21: บริการรับชำระบัตรเครดิตยูโอบี (Online) | C21: 42186 | D21: 15/09/2025 | E21: Closed | F21: ONLINE | G21: บริการรับชำระ | H21: Banking | I21: Credit Card Flow | J21: Standard | K21: 3 | L21: UOB | M21: 0 | N21: 1 | O21: 50000 | P21: 100000 | T21: YES | U21: 31/12/2023 | V21: =VLOOKUP(A21,'2023 Stats'!$B$2:$D$192,3,FALSE) -> 19952 | W21: 4988 | Y21: 27913 | Z21: 2326 | AB21: #N/A | AE21: 3657
A22: 30221 | B22: เงินฝากสมาชิกสิ่งสะสม | C22: 42186 | E22: Open | F22: OFFLINE | G22: บริการรับชำระ | H22: Postal service | M22: 0 | N22: 1 | O22: 50000 | P22: 100000 | S22: O7 | T22: YES | U22: 31/12/2023 | V22: =VLOOKUP(A22,'2023 Stats'!$B$2:$D$192,3,FALSE) -> 589 | W22: 147 | Y22: 589 | Z22: 49 | AB22: #N/A | AE22: 98 | AH22: YES
A23: 50002 | B23: ค่าน้ำประปานครหลวง | C23: 42186 | E23: Open | F23: OFFLINE | G23: บริการตัวการตัวแทน | H23: Utilities | M23: 10 | N23: 1 | O23: 50000 | P23: 100000 | Q23: YES | R23: YES | S23: O7 | T23: YES | U23: 31/12/2023 | V23: =VLOOKUP(A23,'2023 Stats'!$B$2:$D$192,3,FALSE) -> 3720 | W23: 930 | Y23: 4900 | Z23: 408 | AB23: 7621 | AC23: 635 | AE23: 658
A24: 50082 | B24: สินค้าเชื่อ/งวดเงินกู้/บัตรเครดิต AEON | C24: 42186 | D24: 44556 | E24: Closed | F24: OFFLINE | G24: บริการรับชำระ | M24: 0 | N24: 1 | O24: 50000 | P24: 100000 | T24: YES | U24: 44555 | V24: =VLOOKUP(A24,'2023 Stats'!$B$2:$D$192,3,FALSE) -> #N/A | W24: #N/A | Y24: #N/A | Z24: #N/A | AB24: 6055 | AC24: 505 | AE24: #N/A
A25: 50099 | B25: ค่าโทรศัพท์ | C25: 42186 | D25: 42886 | E25: Closed | F25: OFFLINE | G25: บริการตัวการตัวแทน | M25: 0 | N25: 0 | O25: 0 | P25: 100000 | T25: YES | U25: #N/A | V25: =VLOOKUP(A25,'2023 Stats'!$B$2:$D$192,3,FALSE) -> #N/A | W25: #N/A | Y25: #N/A | Z25: #N/A | AB25: #N/A | AE25: #N/A
A26: 50113 | B26: GE ค่า First Choice | C26: 42186 | E26: Open | F26: OFFLINE | G26: บริการรับชำระ | H26: Service payment | I26: Manual input | K26: 4 | M26: 10 | N26: 1 | O26: 50000 | P26: 100000 | T26: YES | U26: 31/12/2023 | V26: =VLOOKUP(A26,'2023 Stats'!$B$2:$D$192,3,FALSE) -> 4185 | W26: 1046 | Y26: 5903 | Z26: 492 | AB26: 10481 | AC26: 873 | AE26: 804
A27: 50115 | B27: GE Power Buy | C27: 42186 | D27: 42886 | E27: Closed | F27: OFFLINE | G27: บริการรับชำระ | M27: 0 | N27: 1 | O27: 50000 | P27: 100000 | T27: YES | U27: #N/A | V27: =VLOOKUP(A27,'2023 Stats'!$B$2:$D$192,3,FALSE) -> #N/A | W27: #N/A | Y27: #N/A | Z27: #N/A | AB27: #N/A | AE27: #N/A
A28: 50116 | B28: GE Central Card | C28: 42186 | E28: Open | F28: OFFLINE | G28: บริการรับชำระ | H28: Service payment | M28: 10 | N28: 1 | O28: 50000 | P28: 100000 | T28: YES | V28: =VLOOKUP(A28,'2023 Stats'!$B$2:$D$192,3,FALSE) -> #N/A | W28: #N/A | Y28: #N/A | Z28: #N/A | AB28: 4 | AC28: 0 | AE28: #N/A
A29: 50117 | B29: ชำระค่างวด AYUDHYA Capital Auto Lease | C29: 42186 | D29: 31/03/2026 | E29: Closed | F29: OFFLINE | G29: บริการรับชำระ | H29: Loan | I29: Scan Bill Only | J29: Standard | K29: 5 | M29: 10 | N29: 1 | O29: 50000 | P29: 100000 | T29: YES | U29: 31/12/2023 | V29: =VLOOKUP(A29,'2023 Stats'!$B$2:$D$192,3,FALSE) -> 4558 | W29: 1140 | Y29: 5863 | Z29: 489 | AB29: 8736 | AC29: 728 | AE29: 785
A30: 50118 | B30: TESCO LOTUS CARD | C30: 42186 | E30: Open | F30: OFFLINE | G30: บริการรับชำระ | H30: Service payment | M30: 10 | N30: 1 | O30: 50000 | P30: 100000 | T30: YES | V30: =VLOOKUP(A30,'2023 Stats'!$B$2:$D$192,3,FALSE) -> #N/A | W30: #N/A | Y30: #N/A | Z30: #N/A | AB30: #N/A | AE30: #N/A
A31: 50122 | B31: GE ค่า Quick Cash บ.โลตัสส์ มันนี่ เซอร์วิสเซส | C31: 42186 | E31: Open | F31: OFFLINE | G31: บริการรับชำระ | H31: Service payment | M31: 10 | N31: 1 | O31: 50000 | P31: 100000 | T31: YES | V31: =VLOOKUP(A31,'2023 Stats'!$B$2:$D$192,3,FALSE) -> 2 | W31: 1 | Y31: #N/A | Z31: #N/A | AB31: 4 | AC31: 0 | AE31: #N/A
A32: 50126 | B32: ชำระภาษีเงินได้ ภงด. | C32: 42186 | E32: Open | F32: OFFLINE | G32: บริการรับชำระ | H32: Service payment | I32: Special Case | J32: No Barcode | K32: 5 | M32: 10 | N32: 1 | O32: 50000 | P32: 100000 | T32: YES | U32: 31/12/2023 | V32: =VLOOKUP(A32,'2023 Stats'!$B$2:$D$192,3,FALSE) -> 19927 | W32: 4982 | Y32: 19122 | Z32: 1594 | AB32: 25347 | AC32: 2112 | AE32: 2896
A33: 50127 | B33: GE HomePro | C33: 42186 | E33: Open | F33: OFFLINE | G33: บริการรับชำระ | H33: Service payment | M33: 0 | N33: 1 | O33: 50000 | P33: 100000 | T33: YES | V33: =VLOOKUP(A33,'2023 Stats'!$B$2:$D$192,3,FALSE) -> #N/A | W33: #N/A | Y33: #N/A | Z33: #N/A | AB33: #N/A | AE33: #N/A
A34: 50131 | B34: ชำระค่าเบี้ยประกัน บ.ฟิลลิปฯ | C34: 42186 | E34: Open | F34: OFFLINE | G34: บริการรับชำระ | H34: Insurance | M34: 0 | N34: 1 | O34: 50000 | P34: 100000 | T34: YES | U34: 31/12/2023 | V34: =VLOOKUP(A34,'2023 Stats'!$B$2:$D$192,3,FALSE) -> 364 | W34: 91 | Y34: 467 | Z34: 39 | AB34: 790 | AC34: 66 | AE34: 65
A35: 50166 | B35: สมัครใหม่/ค่าธรรมเนียม/สัมฤทธิ์ ป.ตรี มสธ. | C35: 42186 | E35: Open | F35: OFFLINE | G35: บริการรับชำระ | H35: University Service | I35: Special Case | J35: Custom | K35: 9 | M35: 10 | N35: 1 | O35: 50000 | P35: 100000 | T35: YES | U35: 31/12/2023 | V35: =VLOOKUP(A35,'2023 Stats'!$B$2:$D$192,3,FALSE) -> 6145 | W35: 1536 | Y35: 10377 | Z35: 865 | AB35: 14353 | AC35: 1196 | AE35: 1199
A36: 50168 | B36: บัตรเครดิต ธ.ไทยพาณิชย์ | C36: 42186 | E36: Closed | F36: OFFLINE | G36: บริการรับชำระ | H36: Banking | M36: 10 | N36: 1 | O36: 50000 | P36: 100000 | T36: YES | U36: 31/12/2023 | V36: =VLOOKUP(A36,'2023 Stats'!$B$2:$D$192,3,FALSE) -> 3002 | W36: 751 | Y36: 4860 | Z36: 405 | AB36: 7598 | AC36: 633 | AE36: 596
A37: 50205 | B37: ชำระเงินสินค้า ออริเฟลม คอสเมติกส์ | C37: 42186 | D37: 25/10,2018 | E37: Closed | F37: OFFLINE | G37: บริการรับชำระ | M37: 0 | N37: 0 | O37: 0 | P37: 100000 | T37: YES | U37: #N/A | V37: =VLOOKUP(A37,'2023 Stats'!$B$2:$D$192,3,FALSE) -> #N/A | W37: #N/A | Y37: #N/A | Z37: #N/A | AB37: #N/A | AE37: #N/A
A38: 50207 | B38: ชำระค่างวด ค่าเบี้ยฯ ค่าต่อทะเบียนรถ | C38: 42186 | E38: Closed | F38: OFFLINE | G38: บริการรับชำระ | H38: Service payment | M38: 0 | N38: 1 | O38: 50000 | P38: 100000 | T38: YES | U38: #N/A | V38: =VLOOKUP(A38,'2023 Stats'!$B$2:$D$192,3,FALSE) -> #N/A | W38: #N/A | Y38: #N/A | Z38: #N/A | AB38: #N/A | AE38: #N/A
A39: 50233 | B39: ชำระเบี้ยประกันไทยประกันชีวิต (Online) | C39: 42186 | E39: Open | F39: ONLINE | G39: บริการรับชำระ | H39: Insurance | I39: Credit Card Flow | J39: Standard | K39: 8 | L39: Thailife | M39: 0 | N39: 1 | O39: 50000 | P39: 100000 | T39: YES | U39: 31/12/2023 | V39: =VLOOKUP(50233,'2023 Stats'!$B$2:$D$192,3,FALSE)+VLOOKUP(51081,'2023 Stats'!$B$2:$D$192,3,FALSE) -> 5821 | W39: 1426 | Y39: 6968 | Z39: 581 | AB39: 8310 | AC39: 693 | AE39: 900
A40: 50235 | B40: ชำระค่า พกง. เบล เมซอง | C40: 42186 | E40: Closed | F40: OFFLINE | G40: บริการรับชำระ | H40: Service payment | M40: 0 | N40: 0 | O40: 0 | P40: 100000 | T40: YES | U40: #N/A | V40: =VLOOKUP(A40,'2023 Stats'!$B$2:$D$192,3,FALSE) -> #N/A | W40: #N/A | Y40: #N/A | Z40: #N/A | AB40: #N/A | AE40: #N/A
...

Sheet 2023 Stats
A1: No | B1: ITEM_CODE | C1: ITEM_NAME | D1: COUNT(*)
A2: 1 | B2: 52021 | C2: ลูกหนี้ค่าฝากส่งเงินเชื่อ (WEB AR) | D2: 217269
A3: 2 | B3: 90037 | C3: รับเงินฝากธ.กรุงไทย(คีย์เลขที่บ/ช) | D3: 183318
A4: 3 | B4: 51074 | C4: ค่าไฟฟ้าส่วนภูมิภาค (บาร์โค๊ดใหม่BOT) | D4: 141687
A5: 4 | B5: 52047 | C5: ค่าปรับจราจร | D5: 134421
A6: 5 | B6: 50982 | C6: ค่าน้ำประปาส่วนภูมิภาค 1 Bar สาขาใหม่ | D6: 63548
A7: 6 | B7: 50787 | C7: วีซ่า/มาสเตอร์ (Visa/Master) มีบาร์โค้ด | D7: 50402
A8: 7 | B8: 50489 | C8: ชำระค่างวดรถ โตโยต้า ลีสซิ่ง(กท-ตจว) | D8: 45466
A9: 8 | B9: 90028 | C9: รับเงินฝากธ.กสิกรไทย(คีย์เลขที่บ/ช) | D9: 44146
A10: 9 | B10: 52043 | C10: ชำระสินเชื่อรถยนต์ (กท-ตจว) | D10: 39575
A11: 10 | B11: 90022 | C11: AIS 3G Online ไม่มีบาร์ | D11: 35899
A12: 11 | B12: 50961 | C12: ชำระเงินธนาคารอาคารสงเคราะห์(ออนไลน์) | D12: 34946
A13: 12 | B13: 50496 | C13: เงินสมทบประกันสังคมของผู้ประกันตน ม.39 | D13: 32704
... A192: 191 | B192: 50259 | C192: ชำระค่าเบี้ยประกันกรุงเทพประกันชีวิต | D192: 1

Sheet 2025 Stats
A1: บริการหลัก | B1: ปี 2568/2025 | C1: Item ID | D1: จำนวนรายการ (ม.ค.-ต.ค.) | E1: มกราคม | H1: กุมภาพันธ์ | K1: มีนาคม | N1: เมษายน | Q1: พฤษภาคม | T1: มิถุนายน | W1: กรกฎาคม | Z1: สิงหาคม | AC1: กันยายน | AF1: ตุลาคม
B2: Service Name | E2: จำนวนเงิน | F2: ปริมาณงาน | G2: รายได้ | H2: จำนวนเงิน | I2: ปริมาณงาน | J2: รายได้ | K2: จำนวนเงิน | L2: ปริมาณงาน | M2: รายได้ | N2: จำนวนเงิน | O2: ปริมาณงาน | P2: รายได้ | Q2: จำนวนเงิน | R2: ปริมาณงาน | S2: รายได้ | T2: จำนวนเงิน | U2: ปริมาณงาน | V2: รายได้ | W2: จำนวนเงิน | X2: ปริมาณงาน | Y2: รายได้ | Z2: จำนวนเงิน | AA2: ปริมาณงาน | AB2: รายได้ | AC2: จำนวนเงิน | AD2: ปริมาณงาน | AE2: รายได้ | AF2: จำนวนเงิน | AG2: ปริมาณงาน | AH2: รายได้
A3: Western Union | B3: จ่ายเงินธนาณัติระหว่างประเทศ WESTERN UNION | C3: 19032 | D3: =SUM(F3,I3,L3,O3,R3,U3,X3,AA3,AD3,AG3) -> 145223 | E3: 126449573 | F3: 12238 | G3: 1898015 | H3: 112080165 | I3: 11219 | J3: 1702391 | K3: 132021837 | L3: 12818 | M3: 2029661 | N3: 361151965 | O3: 35685 | P3: 5684451 | Q3: 124356689 | R3: 12546 | S3: 1972569 | T3: 119613225 | U3: 12446 | V3: 1915200 | W3: 119804395 | X3: 12621 | Y3: 1899667 | Z3: 112382934 | AA3: 11777 | AB3: 1759991 | AC3: 111106306 | AD3: 11775 | AE3: 1744918 | AF3: 119041492 | AG3: 12098 | AH3: 1894896
B4: รับฝากธนาณัติระหว่างประเทศ WESTERN UNION | C4: 19035 | D4: =SUM(F4,I4,L4,O4,R4,U4,X4,AA4,AD4,AG4) -> 7265 | E4: 7467184 | F4: 657 | G4: 181529 | H4: 6796213 | I4: 646 | J4: 184943 | K4: 6567105 | L4: 624 | M4: 168858 | N4: 19061731 | O4: 1656 | P4: 447361 | Q4: 6864099 | R4: 618 | S4: 155490 | T4: 7207824 | U4: 558 | V4: 177817 | W4: 6798121 | X4: 598 | Y4: 172159 | Z4: 7378287 | AA4: 643 | AB4: 182331 | AC4: 8037178 | AD4: 652 | AE4: 200931 | AF4: 7242183 | AG4: 613 | AH4: 170432
A5: Pay@Post | B5: รับชำระค่าสินค้าเรียกเก็บเงินที่บ้าน(TND) | C5: 362752 | D5: =SUM(F5,I5,L5,O5,R5,U5,X5,AA5,AD5,AG5) -> 2064577 | E5: 428167553 | F5: 196216 | G5: 0 | H5: 368062072 | I5: 177708 | J5: 0 | K5: 379128108 | L5: 194366 | M5: 0 | N5: 717444287 | O5: 348662 | P5: 0 | Q5: 391213944 | R5: 195767 | S5: 0 | T5: 347957806 | U5: 181632 | V5: 0 | W5: 366374982 | X5: 188753 | Y5: 0 | Z5: 369630864 | AA5: 189318 | AB5: 0 | AC5: 376295880 | AD5: 191963 | AE5: 0 | AF5: 398006024 | AG5: 200192 | AH5: 0
B6: รับเงินฝากธ.กรุงไทย(คีย์เลขที่บ/ช) | C6: 356627 | D6: =SUM(F6,I6,L6,O6,R6,U6,X6,AA6,AD6,AG6) -> 176194 | E6: 290141452 | F6: 18950 | G6: 189500 | H6: 273725261 | I6: 17173 | J6: 171730 | K6: 267567240 | L6: 16974 | M6: 169740 | N6: 475683578 | O6: 29902 | P6: 299020 | Q6: 229340943 | R6: 14871 | S6: 148710 | T6: 243120902 | U6: 15714 | V6: 157140 | W6: 226263025 | X6: 15253 | Y6: 152530 | Z6: 218855139 | AA6: 14836 | AB6: 148360 | AC6: 246488755 | AD6: 16468 | AE6: 164680 | AF6: 243473070 | AG6: 16053 | AH6: 160530
B7: การยืนยันตัวตน - แอปฯทางรัฐ (สพร./DGA) | C7: 362522 | D7: =SUM(F7,I7,L7,O7,R7,U7,X7,AA7,AD7,AG7) -> 122563 | E7: 0 | F7: 60166 | G7: 0 | H7: 0 | I7: 36169 | J7: 0 | K7: 0 | L7: 13564 | M7: 0 | N7: 0 | O7: 8532 | P7: 0 | Q7: 0 | R7: 880 | S7: 0 | T7: 0 | U7: 183 | V7: 0 | W7: 0 | X7: 2201 | Y7: 0 | Z7: 0 | AA7: 649 | AB7: 0 | AC7: 0 | AD7: 103 | AE7: 0 | AF7: 0 | AG7: 116 | AH7: 0
B8: ค่าปรับจราจร | C8: 363725 | D8: =SUM(F8,I8,L8,O8,R8,U8,X8,AA8,AD8,AG8) -> 72570 | E8: 6956400 | F8: 13929 | G8: 208935 | H8: 6312300 | I8: 12631 | J8: 189465 | K8: 4864250 | L8: 9693 | M8: 145395 | N8: 6575400 | O8: 12994 | P8: 194910 | Q8: 3440850 | R8: 6795 | S8: 101925 | T8: 2574000 | U8: 5082 | V8: 76230 | W8: 1683100 | X8: 3293 | Y8: 49395 | Z8: 1325700 | AA8: 2640 | AB8: 39600 | AC8: 1447200 | AD8: 2873 | AE8: 43095 | AF8: 1332900 | AG8: 2640 | AH8: 39600
B9: ชำระค่าปรับจราจรไม่ยึดใบขับขี่ | C9: 3421 | D9: =SUM(F9,I9,L9,O9,R9,U9,X9,AA9,AD9,AG9) -> 57655 | E9: 4159102 | F9: 7588 | G9: 225720 | H9: 3898100 | I9: 6290 | J9: 182248 | K9: 3673611 | L9: 6021 | M9: 175648 | N9: 6766551 | O9: 12074 | P9: 366256 | Q9: 3104089 | R9: 5344 | S9: 153824 | T9: 3804055 | U9: 6182 | V9: 183304 | W9: 2081800 | X9: 3313 | Y9: 76956 | Z9: 1581600 | AA9: 2482 | AB9: 51568 | AC9: 1846700 | AD9: 2937 | AE9: 60852 | AF9: 3575221 | AG9: 5424 | AH9: 160336
B10: ชำระค่าสินค้า/บริการ123Service มีบาร์ | C10: 3164 | D10: =SUM(F10,I10,L10,O10,R10,U10,X10,AA10,AD10,AG10) -> 53667 | E10: 22868364 | F10: 6402 | G10: 0 | H10: 16664688 | I10: 5021 | J10: 0 | K10: 16228458 | L10: 5042 | M10: 0 | N10: 31427271 | O10: 8832 | P10: 0 | Q10: 14012146 | R10: 4475 | S10: 0 | T10: 15786988 | U10: 4763 | V10: 0 | W10: 15238943 | X10: 4499 | Y10: 0 | Z10: 15150968 | AA10: 4568 | AB10: 0 | AC10: 17380717 | AD10: 5152 | AE10: 0 | AF10: 15770989 | AG10: 4913 | AH10: 0
B11: รับเงินฝากธ.กสิกรไทย(คีย์เลขที่บ/ช) | C11: 356625 | D11: =SUM(F11,I11,L11,O11,R11,U11,X11,AA11,AD11,AG11) -> 39355 | E11: 52755328 | F11: 3886 | G11: 38860 | H11: 47598755 | I11: 3583 | J11: 35830 | K11: 49353925 | L11: 3663 | M11: 36630 | N11: 92693039 | O11: 6784 | P11: 67840 | Q11: 44732688 | R11: 3380 | S11: 33800 | T11: 46554937 | U11: 3527 | V11: 35270 | W11: 47773992 | X11: 3523 | Y11: 35230 | Z11: 43755867 | AA11: 3454 | AB11: 34540 | AC11: 46075193 | AD11: 3771 | AE11: 37710 | AF11: 50110641 | AG11: 3784 | AH11: 37840
B12: ค่าไฟฟ้าส่วนภูมิภาค (Online) | C12: 364371 | D12: =SUM(F12,I12,L12,O12,R12,U12,X12,AA12,AD12,AG12) -> 36538 | E12: 2001444 | F12: 3011 | G12: 30110 | H12: 1847726 | I12: 3042 | J12: 30420 | K12: 2543894 | L12: 3073 | M12: 30730 | N12: 5714910 | O12: 6658 | P12: 66580 | Q12: 3102744 | R12: 3366 | S12: 33660 | T12: 2826100 | U12: 3408 | V12: 34080 | W12: 2763685 | X12: 3420 | Y12: 34200 | Z12: 2844540 | AA12: 3387 | AB12: 33870 | AC12: 2724182 | AD12: 3604 | AE12: 36040 | AF12: 2748268 | AG12: 3569 | AH12: 35690
B13: ค่าน้ำประปาส่วนภูมิภาค 1 Bar สาขาใหม่ | C13: 3181 | D13: =SUM(F13,I13,L13,O13,R13,U13,X13,AA13,AD13,AG13) -> 34717 | E13: 1267077 | F13: 3370 | G13: 33670 | H13: 1192345 | I13: 3487 | J13: 34840 | K13: 1053351 | L13: 3398 | M13: 33940 | N13: 2313389 | O13: 6306 | P13: 63020 | Q13: 1034513 | R13: 3049 | S13: 30450 | T13: 1025221 | U13: 3136 | V13: 31330 | W13: 953938 | X13: 2986 | Y13: 29830 | Z13: 1001292 | AA13: 3024 | AB13: 30210 | AC13: 992529 | AD13: 3050 | AE13: 30460 | AF13: 844982 | AG13: 2911 | AH13: 29070
B14: AIS 3G Online ไม่มีบาร์ | C14: 3261 | D14: =SUM(F14,I14,L14,O14,R14,U14,X14,AA14,AD14,AG14) -> 29771 | E14: 1602880 | F14: 2937 | G14: 44055 | H14: 1441821 | I14: 2609 | J14: 39135 | K14: 1468296 | L14: 2725 | M14: 40875 | N14: 2902221 | O14: 5178 | P14: 77670 | Q14: 1459644 | R14: 2624 | S14: 39360 | T14: 1386497 | U14: 2522 | V14: 37830 | W14: 1437423 | X14: 2588 | Y14: 38820 | Z14: 1439296 | AA14: 2536 | AB14: 38040 | AC14: 1478794 | AD14: 2626 | AE14: 39390 | AF14: 1898543 | AG14: 3426 | AH14: 51390
B15: รับฝากเงินธ. ไทยพาณิชย์(คีย์เลขที่บ/ช) | C15: 356626 | D15: =SUM(F15,I15,L15,O15,R15,U15,X15,AA15,AD15,AG15) -> 29344 | E15: 41750975 | F15: 2918 | G15: 29180 | H15: 40819880 | I15: 2783 | J15: 27830 | K15: 34605878 | L15: 2493 | M15: 24930 | N15: 61166379 | O15: 4300 | P15: 43000 | Q15: 41193612 | R15: 2675 | S15: 26750 | T15: 44441536 | U15: 2885 | V15: 28850 | W15: 44443549 | X15: 2929 | Y15: 29290 | Z15: 45365787 | AA15: 2913 | AB15: 29130 | AC15: 42235987 | AD15: 2933 | AE15: 29330 | AF15: 33171674 | AG15: 2515 | AH15: 25150
B16: รับชำระ Fuze Post | C16: 363745 | D16: =SUM(F16,I16,L16,O16,R16,U16,X16,AA16,AD16,AG16) -> 26847 | E16: 1533986 | F16: 1626 | G16: 0 | H16: 1460626 | I16: 1621 | J16: 0 | K16: 1699522 | L16: 2002 | M16: 0 | N16: 3489860 | O16: 3556 | P16: 0 | Q16: 2066748 | R16: 2338 | S16: 0 | T16: 2331515 | U16: 2926 | V16: 0 | W16: 2347219 | X16: 3073 | Y16: 0 | Z16: 2248448 | AA16: 2923 | AB16: 0 | AC16: 2534749 | AD16: 3456 | AE16: 0 | AF16: 2413125 | AG16: 3326 | AH16: 0
B17: ชำระเงินบัตรเครดิตธนาคารUOBธ.เอเซียเดิม | C17: 3323 | D17: =SUM(F17,I17,L17,O17,R17,U17,X17,AA17,AD17,AG17) -> 25595 | E17: 23213116 | F17: 2735 | G17: 27350 | H17: 23067115 | I17: 2746 | J17: 27460 | K17: 23876179 | L17: 2890 | M17: 28900 | N17: 43624190 | O17: 5588 | P17: 55880 | Q17: 21852242 | R17: 2774 | S17: 27740 | T17: 22242576 | U17: 2704 | V17: 27040 | W17: 23972051 | X17: 2803 | Y17: 28030 | Z17: 19684299 | AA17: 2376 | AB17: 23760 | AC17: 8199053 | AD17: 979 | AE17: 9790
B18: ชำระค่างวดรถ โตโยต้า ลีสซิ่ง(กท-ตจว) | C18: 2891 | D18: =SUM(F18,I18,L18,O18,R18,U18,X18,AA18,AD18,AG18) -> 23441 | E18: 39513006 | F18: 2741 | G18: 40295 | H18: 35007864 | I18: 2509 | J18: 36845 | K18: 33487188 | L18: 2387 | M18: 35025 | N18: 53877249 | O18: 4310 | P18: 63310 | Q18: 23911224 | R18: 2034 | S18: 29880 | T18: 21760177 | U18: 1967 | V18: 28810 | W18: 22201887 | X18: 1941 | Y18: 28500 | Z18: 20626224 | AA18: 1808 | AB18: 26500 | AC18: 20845610 | AD18: 1869 | AE18: 27465 | AF18: 22215041 | AG18: 1875 | AH18: 27550
B19: เงินสมทบประกันสังคมของผู้ประกันตน ม.39 | C19: 2895 | D19: =SUM(F19,I19,L19,O19,R19,U19,X19,AA19,AD19,AG19) -> 22444 | E19: 772237 | F19: 2490 | G19: 24900 | H19: 768493 | I19: 2494 | J19: 24940 | K19: 715671 | L19: 2312 | M19: 23120 | N19: 1618610 | O19: 4110 | P19: 41100 | Q19: 835920 | R19: 1935 | S19: 19350 | T19: 799632 | U19: 1851 | V19: 18510 | W19: 807408 | X19: 1869 | Y19: 18690 | Z19: 792720 | AA19: 1835 | AB19: 18350 | AC19: 763776 | AD19: 1768 | AE19: 17680 | AF19: 768960 | AG19: 1780 | AH19: 17800
B20: ชำระสินเชื่อรถยนต์ (กท-ตจว) | C20: 360014 | D20: =SUM(F20,I20,L20,O20,R20,U20,X20,AA20,AD20,AG20) -> 19879 | E20: 21767254 | F20: 2133 | G20: 31515 | H20: 19555525 | I20: 1998 | J20: 29470 | K20: 19430466 | L20: 1986 | M20: 29215 | N20: 35114424 | O20: 3690 | P20: 54340 | Q20: 16693607 | R20: 1772 | S20: 26095 | T20: 15764537 | U20: 1716 | V20: 25280 | W20: 15331926 | X20: 1717 | Y20: 25235 | Z20: 14563695 | AA20: 1614 | AB20: 23785 | AC20: 15852473 | AD20: 1664 | AE20: 24470 | AF20: 14728848 | AG20: 1589 | AH20: 23380
B21: สินเชื่อรถยนต์ ธนาคารกรุงศรีอยุธยา | C21: 3191 | D21: =SUM(F21,I21,L21,O21,R21,U21,X21,AA21,AD21,AG21) -> 19145 | E21: 16644373 | F21: 2169 | G21: 21690 | H21: 15423398 | I21: 1954 | J21: 19540 | K21: 15302490 | L21: 1996 | M21: 19960 | N21: 27275365 | O21: 3596 | P21: 35960 | Q21: 12480566 | R21: 1647 | S21: 16470 | T21: 12864847 | U21: 1669 | V21: 16690 | W21: 12247057 | X21: 1609 | Y21: 16090 | Z21: 10986426 | AA21: 1497 | AB21: 14970 | AC21: 11224512 | AD21: 1502 | AE21: 15020 | AF21: 11075927 | AG21: 1506 | AH21: 15060
B22: ชำระบริการต่าง ๆ ของคุรุสภา มีบาร์โค้ด | C22: 30119 | D22: =SUM(F22,I22,L22,O22,R22,U22,X22,AA22,AD22,AG22) -> 18813 | E22: 907700 | F22: 2359 | G22: 23590 | H22: 784900 | I22: 2074 | J22: 20740 | K22: 963600 | L22: 2336 | M22: 23360 | N22: 2417600 | O22: 4510 | P22: 45100 | Q22: 1277800 | R22: 1964 | S22: 19640 | T22: 845100 | U22: 1403 | V22: 14030 | W22: 719200 | X22: 1256 | Y22: 12560 | Z22: 685500 | AA22: 1218 | AB22: 12180 | AC22: 530100 | AD22: 844 | AE22: 8440 | AF22: 504700 | AG22: 849 | AH22: 8490
B23: ชำระเงินธนาคารอาคารสงเคราะห์(ออนไลน์) | C23: 3169 | D23: =SUM(F23,I23,L23,O23,R23,U23,X23,AA23,AD23,AG23) -> 18649 | E23: 8458532 | F23: 1915 | G23: 19150 | H23: 8257414 | I23: 1814 | J23: 18140 | K23: 8672526 | L23: 1826 | M23: 18260 | N23: 15427079 | O23: 3498 | P23: 34980 | Q23: 7658460 | R23: 1669 | S23: 16690 | T23: 7083825 | U23: 1600 | V23: 16000 | W23: 7021054 | X23: 1663 | Y23: 16630 | Z23: 6814313 | AA23: 1584 | AB23: 15840 | AC23: 6527255 | AD23: 1545 | AE23: 15450 | AF23: 6822562 | AG23: 1535 | AH23: 15350
B24: ชำระค่างวด บ.ตรีเพชรอีซูซุลิสซิ่ง จำกัด | C24: 3210 | D24: =SUM(F24,I24,L24,O24,R24,U24,X24,AA24,AD24,AG24) -> 17098 | E24: 21261876 | F24: 1794 | G24: 26910 | H24: 21035348 | I24: 1704 | J24: 25560 | K24: 18596224 | L24: 1594 | M24: 23910 | N24: 35946136 | O24: 3160 | P24: 47400 | Q24: 15229854 | R24: 1450 | S24: 21750 | T24: 14991108 | U24: 1408 | V24: 21120 | W24: 15395950 | X24: 1472 | Y24: 22080 | Z24: 13951522 | AA24: 1364 | AB24: 20460 | AC24: 14630818 | AD24: 1480 | AE24: 22200 | AF24: 17464378 | AG24: 1672 | AH24: 25080
B25: ค่าโทรศัพท์ TOT ใหม่ | C25: 2829 | D25: =SUM(F25,I25,L25,O25,R25,U25,X25,AA25,AD25,AG25) -> 16911 | E25: 699312 | F25: 1762 | G25: 17620 | H25: 612544 | I25: 1611 | J25: 16110 | K25: 648339 | L25: 1663 | M25: 16630 | N25: 1185623 | O25: 3010 | P25: 30100 | Q25: 564058 | R25: 1471 | S25: 14710 | T25: 570077 | U25: 1458 | V25: 14580 | W25: 575383 | X25: 1466 | Y25: 14660 | Z25: 580327 | AA25: 1524 | AB25: 15240 | AC25: 573857 | AD25: 1467 | AE25: 14670 | AF25: 576034 | AG25: 1479 | AH25: 14790
B26: ชำระค่าบริการ บัตรชำระบุญเติม มีบาร์ | C26: 2684 | D26: =SUM(F26,I26,L26,O26,R26,U26,X26,AA26,AD26,AG26) -> 15999 | E26: 10270047 | F26: 1667 | G26: 25005 | H26: 8705573 | I26: 1429 | J26: 21435 | K26: 9241770 | L26: 1486 | M26: 22290 | N26: 16698374 | O26: 2590 | P26: 38850 | Q26: 8150452 | R26: 1324 | S26: 19860 | T26: 7971638 | U26: 1252 | V26: 18780 | W26: 7672876 | X26: 1251 | Y26: 18765 | Z26: 7691516 | AA26: 1251 | AB26: 18765 | AC26: 7959499 | AD26: 1350 | AE26: 20250 | AF26: 13285345 | AG26: 2399 | AH26: 35985
B27: ชำระภาษีเงินได้ ภงด. | C27: 2693 | D27: =SUM(F27,I27,L27,O27,R27,U27,X27,AA27,AD27,AG27) -> 15399 | E27: 2844106 | F27: 1520 | G27: 15200 | H27: 4435434 | I27: 1728 | J27: 17280 | K27: 9720563 | L27: 3331 | M27: 33310 | N27: 9848838 | O27: 2902 | P27: 29020 | Q27: 3684101 | R27: 831 | S27: 8310 | T27: 2903262 | U27: 714 | V27: 7140 | W27: 2124468 | X27: 920 | Y27: 9200 | Z27: 2371000 | AA27: 973 | AB27: 9730 | AC27: 2941987 | AD27: 1668 | AE27: 16680 | AF27: 2302499 | AG27: 812 | AH27: 8120
B28: ค่างวดเครื่องจักร/บริการอื่นสยามคูโบต้า | C28: 3129 | D28: =SUM(F28,I28,L28,O28,R28,U28,X28,AA28,AD28,AG28) -> 15154 | E28: 39526216 | F28: 2104 | G28: 21040 | H28: 32591526 | I28: 1796 | J28: 17960 | K28: 29708286 | L28: 1717 | M28: 17170 | N28: 52585953 | O28: 3006 | P28: 30060 | Q28: 24637487 | R28: 1444 | S28: 14440 | T28: 18455550 | U28: 1202 | V28: 12020 | W28: 10990303 | X28: 1055 | Y28: 10550 | Z28: 9017678 | AA28: 931 | AB28: 9310 | AC28: 9192523 | AD28: 950 | AE28: 9500 | AF28: 10708817 | AG28: 949 | AH28: 9490
B29: รับเงินฝากธ.กรุงเทพ(คีย์เลขที่บ/ช) | C29: 356628 | D29: =SUM(F29,I29,L29,O29,R29,U29,X29,AA29,AD29,AG29) -> 10603 | E29: 15368120 | F29: 1125 | G29: 11250 | H29: 12787420 | I29: 965 | J29: 9650 | K29: 12669888 | L29: 971 | M29: 9710 | N29: 26448438 | O29: 1962 | P29: 19620 | Q29: 11017213 | R29: 875 | S29: 8750 | T29: 11671133 | U29: 957 | V29: 9570 | W29: 13191111 | X29: 1023 | Y29: 10230 | Z29: 11108292 | AA29: 824 | AB29: 8240 | AC29: 11602319 | AD29: 907 | AE29: 9070 | AF29: 13369330 | AG29: 994 | AH29: 9940
... B42: รับเงินฝากธ.ซีไอเอ็มบีไทย(คีย์เลขที่บ/ช) | C42: 3254 | D42: =SUM(F42,I42,L42,O42,R42,U42,X42,AA42,AD42,AG42) -> 3911 | E42: 4462571 | F42: 383 | G42: 5745 | H42: 4708398 | I42: 418 | J42: 6270 | K42: 4715743 | L42: 397 | M42: 5955 | N42: 8586739 | O42: 692 | P42: 10380 | Q42: 3232804 | R42: 299 | S42: 4485 | T42: 4488559 | U42: 358 | V42: 5370 | W42: 3771508 | X42: 322 | Y42: 4830 | Z42: 3782661 | AA42: 326 | AB42: 4890 | AC42: 3816133 | AD42: 355 | AE42: 5325 | AF42: 4036360 | AG42: 361 | AH42: 5415
B43: ชำระค่าธรรมเนียม กรมธุรกิจพลังงาน | C43: 364544 | D43: =SUM(F43,I43,L43,O43,R43,U43,X43,AA43,AD43,AG43) -> 3899 | H43: 1484902 | I43: 1156 | J43: 17340 | K43: 778554 | L43: 577 | M43: 8655 | N43: 1509737 | O43: 1018 | P43: 15270 | Q43: 611113 | R43: 444 | S43: 6660 | T43: 329199 | U43: 259 | V43: 3885 | W43: 205503 | X43: 161 | Y43: 2415 | Z43: 190274 | AA43: 123 | AB43: 1845 | AC43: 160320 | AD43: 112 | AE43: 1680 | AF43: 84609 | AG43: 49 | AH43: 735
B44: รับชำระ บัตรเครดิต/บัตรกดเงินสด (กท-ตจว) | C44: 359333 | D44: =SUM(F44,I44,L44,O44,R44,U44,X44,AA44,AD44,AG44) -> 3300 | E44: 1397058 | F44: 377 | G44: 5190 | H44: 1051535 | I44: 290 | J44: 4045 | K44: 1247715 | L44: 317 | M44: 4340 | N44: 2552307 | O44: 642 | P44: 8800 | Q44: 1078835 | R44: 281 | S44: 3925 | T44: 1096253 | U44: 277 | V44: 3810 | W44: 1159283 | X44: 303 | Y44: 4190 | Z44: 987580 | AA44: 266 | AB44: 3695 | AC44: 916453 | AD44: 269 | AE44: 3760 | AF44: 1327679 | AG44: 278 | AH44: 3830
B45: รับเงินฝากธ.กรุงศรีอยุธยา(คีย์เลขที่บ/ช) | C45: 3253 | D45: =SUM(F45,I45,L45,O45,R45,U45,X45,AA45,AD45,AG45) -> 3261 | E45: 5800672 | F45: 307 | G45: 3070 | H45: 5584495 | I45: 293 | J45: 2930 | K45: 5716351 | L45: 289 | M45: 2890 | N45: 13209436 | O45: 606 | P45: 6060 | Q45: 5763751 | R45: 271 | S45: 2710 | T45: 6569577 | U45: 324 | V45: 3240 | W45: 5406548 | X45: 282 | Y45: 2820 | Z45: 5770776 | AA45: 267 | AB45: 2670 | AC45: 6012410 | AD45: 312 | AE45: 3120 | AF45: 5858707 | AG45: 310 | AH45: 3100
B46: ชำระค่างวด AYUDHYA Capital Auto Lease | C46: 2689 | D46: =SUM(F46,I46,L46,O46,R46,U46,X46,AA46,AD46,AG46) -> 3200 | E46: 730765 | F46: 353 | G46: 3530 | H46: 720234 | I46: 291 | J46: 2910 | K46: 838939 | L46: 301 | M46: 3010 | N46: 1390369 | O46: 582 | P46: 5820 | Q46: 625554 | R46: 313 | S46: 3130 | T46: 570117 | U46: 283 | V46: 2830 | W46: 578144 | X46: 270 | Y46: 2700 | Z46: 518160 | AA46: 259 | AB46: 2590 | AC46: 545172 | AD46: 282 | AE46: 2820 | AF46: 594793 | AG46: 266 | AH46: 2660
B47: ชำระค่าบริการ บัตรชำระบุญเติม ไม่มีบาร์ | C47: 2692 | D47: =SUM(F47,I47,L47,O47,R47,U47,X47,AA47,AD47,AG47) -> 2789 | E47: 1641323 | F47: 303 | G47: 4545 | H47: 1483220 | I47: 254 | J47: 3810 | K47: 1421689 | L47: 269 | M47: 4035 | N47: 2893460 | O47: 460 | P47: 6900 | Q47: 1581250 | R47: 236 | S47: 3540 | T47: 1350983 | U47: 226 | V47: 3390 | W47: 1274520 | X47: 224 | Y47: 3360 | Z47: 1316751 | AA47: 244 | AB47: 3660 | AC47: 1497405 | AD47: 261 | AE47: 3915 | AF47: 1663920 | AG47: 312 | AH47: 4680
B48: ชำระค่าธรรมเนียมโอนชุดวิชา มสธ. | C48: 2928 | D48: =SUM(F48,I48,L48,O48,R48,U48,X48,AA48,AD48,AG48) -> 2604 | E48: 108451 | F48: 234 | G48: 2340 | H48: 89301 | I48: 200 | J48: 2000 | K48: 119500 | L48: 302 | M48: 3020 | N48: 143600 | O48: 234 | P48: 2340 | Q48: 63250 | R48: 116 | S48: 1160 | T48: 270000 | U48: 619 | V48: 6190 | W48: 119800 | X48: 251 | Y48: 2510 | Z48: 118400 | AA48: 284 | AB48: 2840 | AC48: 122900 | AD48: 278 | AE48: 2780 | AF48: 39500 | AG48: 86 | AH48: 860
B49: ชำระค่าเช่าที่ราชพัสดุ กรมธนารักษ์ | C49: 3036 | D49: =SUM(F49,I49,L49,O49,R49,U49,X49,AA49,AD49,AG49) -> 2517 | E49: 484058 | F49: 510 | G49: 7650 | H49: 1456006 | I49: 1099 | J49: 16485 | K49: 288456 | L49: 300 | M49: 4500 | N49: 304926 | O49: 208 | P49: 3120 | Q49: 139601 | R49: 115 | S49: 1725 | T49: 66866 | U49: 72 | V49: 1080 | W49: 183683 | X49: 79 | Y49: 1185 | Z49: 115440 | AA49: 50 | AB49: 750 | AC49: 61153 | AD49: 35 | AE49: 525 | AF49: 120534 | AG49: 49 | AH49: 735
B50: ธนาณัติชำระค่าปรับจราจร | C50: 3406 | D50: =SUM(F50,I50,L50,O50,R50,U50,X50,AA50,AD50,AG50) -> 2476 | E50: 293560 | F50: 417 | G50: 22680 | H50: 374978 | I50: 332 | J50: 18816 | K50: 363190 | L50: 329 | M50: 18480 | N50: 349060 | O50: 536 | P50: 31920 | Q50: 216530 | R50: 248 | S50: 13944 | T50: 121450 | U50: 198 | V50: 10920 | W50: 94162 | X50: 142 | Y50: 5712 | Z50: 39400 | AA50: 64 | AB50: 2184 | AC50: 48300 | AD50: 95 | AE50: 3864 | AF50: 84900 | AG50: 115 | AH50: 7056
B51: ชำระค่าสินค้า ยันมาร์แคปปิตอล | C51: 3067 | D51: =SUM(F51,I51,L51,O51,R51,U51,X51,AA51,AD51,AG51) -> 2433 | E51: 3783098 | F51: 255 | G51: 3825 | H51: 2708709 | I51: 239 | J51: 3585 | K51: 3772849 | L51: 243 | M51: 3645 | N51: 6408420 | O51: 470 | P51: 7050 | Q51: 3755350 | R51: 242 | S51: 3630 | T51: 3260625 | U51: 221 | V51: 3315 | W51: 1665783 | X51: 189 | Y51: 2835 | Z51: 1747946 | AA51: 191 | AB51: 2865 | AC51: 1853744 | AD51: 203 | AE51: 3045 | AF51: 1166932 | AG51: 180 | AH51: 2700
B52: บัครเครดิต KTC Barcode 1 แถว(กท-ตจว) | C52: 2943 | D52: =SUM(F52,I52,L52,O52,R52,U52,X52,AA52,AD52,AG52) -> 2307 | E52: 1295363 | F52: 248 | G52: 4630 | H52: 1160682 | I52: 205 | J52: 3870 | K52: 1242482 | L52: 230 | M52: 4270 | N52: 2077885 | O52: 434 | P52: 8050 | Q52: 1144110 | R52: 210 | S52: 3955 | T52: 865306 | U52: 184 | V52: 3430 | W52: 833130 | X52: 185 | Y52: 3495 | Z52: 934839 | AA52: 185 | AB52: 3475 | AC52: 960373 | AD52: 173 | AE52: 3245 | AF52: 1370471 | AG52: 253 | AH52: 4830
...
